Workbook

Sheet EXCEL SMX
A1: R | B1: PROVE | C1: LOC | D1: FEC ENTR | E1: FEC CANC | F1: T | G1: NUMPED
A2: 1 | B2: 03292 | C2: 100 | D2: 20220713 | E2: 20220713 | F2: 0 | G2: 725359
A3: R | B3: CODIGO BARRAS | C3: DESCRIPCION ARTICULO | D3: CODIGO REFER | E3: TALLA | F3: COLOR | G3: TAMANO | H3: MARCA | I3: UNMA | J3: PREC. COSTO | K3: DESC 1 | L3: DESC 2 | M3: DESC 3 | N3: DESC 4 | O3: DESDOC | P3: DESPRO | Q3: DEPROM | R3: DESESP | S3: CANTID | T3: PESO | U3: IVA | V3: NUMERO ORDEN
A4: 2 | B4: 7861033002552 | C4: LA HOLANDESA MIX QUESO PICADIT | D4: 7861033002552 | G4: 300 g | H4: LA HOLANDESA | I4: 0008 | J4: 3,8000 | K4: 0,00 | L4: 0,00 | M4: 0,00 | N4: 0,00 | O4: 0,00 | P4: 0,00 | Q4: 20,00 | R4: 0,00 | S4: 000023 | T4: 0,000 | U4: 0,00 | V4: 100219388526
A5: 2 | B5: 7861033000640 | C5: LA HOLANDESA Q.CHEDDAR | D5: Rebanado 200gr | G5: 200g | H5: LA HOLANDESA | I5: 0024 | J5: 2,7900 | K5: 0,00 | L5: 0,00 | M5: 0,00 | N5: 0,00 | O5: 0,00 | P5: 0,00 | Q5: 0,00 | R5: 0,00 | S5: 000005 | T5: 0,000 | U5: 0,00 | V5: 100219388526
A6: 2 | B6: 7861033000657 | C6: LA HOLANDESA Q.CHEDDAR | D6: Rebanado 400gr | G6: 400g | H6: LA HOLANDESA | I6: 0012 | J6: 5,4000 | K6: 0,00 | L6: 0,00 | M6: 0,00 | N6: 0,00 | O6: 0,00 | P6: 0,00 | Q6: 20,00 | R6: 0,00 | S6: 000012 | T6: 0,000 | U6: 0,00 | V6: 100219388526
A7: 2 | B7: 7861033000626 | C7: LA HOLANDESA Q.HOLANDES REB. | D7: REBANADO | G7: 200g | H7: LA HOLANDESA | I7: 0024 | J7: 2,8000 | K7: 0,00 | L7: 0,00 | M7: 0,00 | N7: 0,00 | O7: 0,00 | P7: 0,00 | Q7: 20,00 | R7: 0,00 | S7: 000007 | T7: 0,000 | U7: 0,00 | V7: 100219388526
A8: 2 | B8: 7861033000633 | C8: LA HOLANDESA Q.HOLANDES REB. | D8: PT558 | G8: 400g | H8: LA HOLANDESA | I8: 0012 | J8: 5,4000 | K8: 0,00 | L8: 0,00 | M8: 0,00 | N8: 0,00 | O8: 0,00 | P8: 0,00 | Q8: 0,00 | R8: 0,00 | S8: 000006 | T8: 0,000 | U8: 0,00 | V8: 100219388526
A9: 2 | B9: 7861033000602 | C9: LA HOLANDESA Q.MOZZARELLA REB | D9: REBANADO | G9: 200g | H9: LA HOLANDESA | I9: 0024 | J9: 2,8000 | K9: 0,00 | L9: 0,00 | M9: 0,00 | N9: 0,00 | O9: 0,00 | P9: 0,00 | Q9: 0,00 | R9: 0,00 | S9: 000003 | T9: 0,000 | U9: 0,00 | V9: 100219388526
A10: 2 | B10: 7861033000619 | C10: LA HOLANDESA Q.MOZZARELLA REB. | D10: REBANADO PT556 | G10: 400g | H10: LA HOLANDESA | I10: 0012 | J10: 5,4000 | K10: 0,00 | L10: 0,00 | M10: 0,00 | N10: 0,00 | O10: 0,00 | P10: 0,00 | Q10: 0,00 | R10: 0,00 | S10: 000004 | T10: 0,000 | U10: 0,00 | V10: 100219388526
A11: 2 | B11: 7861042572244 | C11: LO.QUESO AMERICANO REBANADO | D11: 7861042572244 | G11: 1kg | H11: LA ORIGINAL | I11: 0004 | J11: 8,9500 | K11: 0,00 | L11: 0,00 | M11: 0,00 | N11: 0,00 | O11: 0,00 | P11: 0,00 | Q11: 0,00 | R11: 0,00 | S11: 000001 | T11: 0,000 | U11: 0,00 | V11: 100219388526
A12: 2 | B12: 7861042572688 | C12: LO.QUESO CHEDAR REBANADO | D12: 7861042572688 | G12: 150g | H12: LA ORIGINAL | I12: 0012 | J12: 1,6500 | K12: 0,00 | L12: 0,00 | M12: 0,00 | N12: 0,00 | O12: 0,00 | P12: 0,00 | Q12: 0,00 | R12: 0,00 | S12: 000045 | T12: 0,000 | U12: 0,00 | V12: 100219388526
A13: 2 | B13: 7861042570141 | C13: LO.QUESO HOLANDES REBANADO | D13: 7861042570141 | G13: 150g | H13: LA ORIGINAL | I13: 0012 | J13: 1,6500 | K13: 0,00 | L13: 0,00 | M13: 0,00 | N13: 0,00 | O13: 0,00 | P13: 0,00 | Q13: 0,00 | R13: 0,00 | S13: 000037 | T13: 0,000 | U13: 0,00 | V13: 100219388526
A14: 2 | B14: 7861033001364 | C14: LA HOLANDESA Q.CRIOLLO | D14: 7861033001364 | G14: 700 g | H14: LA HOLANDESA | I14: 0018 | J14: 5,1600 | K14: 0,00 | L14: 0,00 | M14: 0,00 | N14: 0,00 | O14: 0,00 | P14: 0,00 | Q14: 20,00 | R14: 0,00 | S14: 000032 | T14: 0,000 | U14: 0,00 | V14: 100219388526
A15: 2 | B15: 7861033000350 | C15: LA HOLANDESA Q.CRIOLLO CREMOSO | D15: PT530 | G15: 400 g | H15: LA HOLANDESA | I15: 0024 | J15: 3,0500 | K15: 0,00 | L15: 0,00 | M15: 0,00 | N15: 0,00 | O15: 0,00 | P15: 0,00 | Q15: 0,00 | R15: 0,00 | S15: 000003 | T15: 0,000 | U15: 0,00 | V15: 100219388526
... A58: 2 | B58: 7861042574637 | C58: LO.CREMA DE LECHE | D58: 7861042574637 | G58: 200 g | H58: LA ORIGINAL | I58: 0012 | J58: 0,4600 | K58: 0,00 | L58: 0,00 | M58: 0,00 | N58: 0,00 | O58: 0,00 | P58: 0,00 | Q58: 0,00 | R58: 0,00 | S58: 000108 | T58: 0,000 | U58: 0,12 | V58: 100219388528
A59: R | B59: TOTOR | C59: TOTAL COSTO | D59: TOTAL DESC | E59: TOTAL IVA | F59: T.ITEM | G59: TOT BULTS | H59: TOTAL PESO
A60: 3 | B60: 00003 | C60: 30522,0300 | D60: 3509,0899 | E60: 405,7200 | F60: 000055 | G60: 000000957 | H60: 0,000

Sheet Hoja2
B3: NOMBRE | C3: TELEFONO | D3: DIRECCION | E3: SECTOR | F3: TOTAL
B4: Carlos Pérez Paz | C4: 984465560 | D4: Sector Norte de Quito: El Labrador, Isaac Albéniz y Pablo Casals, Pasaje N46e Casa 87. | E4: El Labrador. | F4: 4 canastas

Sheet FINAL BODEGA
A1: COD. | B1: PRODUCTO | C1: UND | D1: # CAJAS | E1: UNIDAD | F1: VALOR | G1: DESCTO. | H1: USD
A2: 7861033000350 | B2: Q. CRIOLLO 400 GR (UN) | C2: =+IFERROR(VLOOKUP(TEXT(A2,"#"),'EXCEL SMX'!B:I,8,0),0) -> 0024 | D2: =IFERROR(VLOOKUP(TEXT(A2,"#"),'EXCEL SMX'!B:S,18,0),0) -> 000003 | E2: =C2*D2 -> 72 | F2: =IFERROR(_xlfn.NUMBERVALUE(SUBSTITUTE(VLOOKUP(TEXT(A2,"#"),'EXCEL SMX'!B:Q,9,0),",",".")),"0")*E2 -> 219.6 | G2: =IFERROR(_xlfn.NUMBERVALUE(SUBSTITUTE(VLOOKUP(TEXT(A2,"#"),'EXCEL SMX'!B:Q,16,0),",","."))/100,"0")*F2 -> 0 | H2: =F2-G2 -> 219.6
A3: 7861033001364 | B3: Q. CRIOLLO 700 GR (UN) | C3: =+IFERROR(VLOOKUP(TEXT(A3,"#"),'EXCEL SMX'!B:I,8,0),0) -> 0018 | D3: =IFERROR(VLOOKUP(TEXT(A3,"#"),'EXCEL SMX'!B:S,18,0),0) -> 000032 | E3: =C3*D3 -> 576 | F3: =IFERROR(_xlfn.NUMBERVALUE(SUBSTITUTE(VLOOKUP(TEXT(A3,"#"),'EXCEL SMX'!B:Q,9,0),",",".")),"0")*E3 -> 2972.16 | G3: =IFERROR(_xlfn.NUMBERVALUE(SUBSTITUTE(VLOOKUP(TEXT(A3,"#"),'EXCEL SMX'!B:Q,16,0),",","."))/100,"0")*F3 -> 594.432 | H3: =F3-G3 -> 2377.728
A4: 7861033001067 | B4: Q. F DE MESA 350 GR (UN) | C4: =+IFERROR(VLOOKUP(TEXT(A4,"#"),'EXCEL SMX'!B:I,8,0),0) -> 0 | D4: =IFERROR(VLOOKUP(TEXT(A4,"#"),'EXCEL SMX'!B:S,18,0),0) -> 0 | E4: =C4*D4 -> 0 | F4: =IFERROR(_xlfn.NUMBERVALUE(SUBSTITUTE(VLOOKUP(TEXT(A4,"#"),'EXCEL SMX'!B:Q,9,0),",",".")),"0")*E4 -> 0 | G4: =IFERROR(_xlfn.NUMBERVALUE(SUBSTITUTE(VLOOKUP(TEXT(A4,"#"),'EXCEL SMX'!B:Q,16,0),",","."))/100,"0")*F4 -> 0 | H4: =F4-G4 -> 0
A5: 7861033002507 | B5: Q. FRESCO 450 GR (UN) | C5: =+IFERROR(VLOOKUP(TEXT(A5,"#"),'EXCEL SMX'!B:I,8,0),0) -> 0012 | D5: =IFERROR(VLOOKUP(TEXT(A5,"#"),'EXCEL SMX'!B:S,18,0),0) -> 000005 | E5: =C5*D5 -> 60 | F5: =IFERROR(_xlfn.NUMBERVALUE(SUBSTITUTE(VLOOKUP(TEXT(A5,"#"),'EXCEL SMX'!B:Q,9,0),",",".")),"0")*E5 -> 192.6 | G5: =IFERROR(_xlfn.NUMBERVALUE(SUBSTITUTE(VLOOKUP(TEXT(A5,"#"),'EXCEL SMX'!B:Q,16,0),",","."))/100,"0")*F5 -> 0 | H5: =F5-G5 -> 192.6
A6: 7861033000312 | B6: Q. FRESCO 700 GR (UN) | C6: =+IFERROR(VLOOKUP(TEXT(A6,"#"),'EXCEL SMX'!B:I,8,0),0) -> 0008 | D6: =IFERROR(VLOOKUP(TEXT(A6,"#"),'EXCEL SMX'!B:S,18,0),0) -> 000011 | E6: =C6*D6 -> 88 | F6: =IFERROR(_xlfn.NUMBERVALUE(SUBSTITUTE(VLOOKUP(TEXT(A6,"#"),'EXCEL SMX'!B:Q,9,0),",",".")),"0")*E6 -> 440.88 | G6: =IFERROR(_xlfn.NUMBERVALUE(SUBSTITUTE(VLOOKUP(TEXT(A6,"#"),'EXCEL SMX'!B:Q,16,0),",","."))/100,"0")*F6 -> 0 | H6: =F6-G6 -> 440.88
A7: 7861033000831 | B7: Q. FRESCO BEG 450 GR (UN) | C7: =+IFERROR(VLOOKUP(TEXT(A7,"#"),'EXCEL SMX'!B:I,8,0),0) -> 0018 | D7: =IFERROR(VLOOKUP(TEXT(A7,"#"),'EXCEL SMX'!B:S,18,0),0) -> 000006 | E7: =C7*D7 -> 108 | F7: =IFERROR(_xlfn.NUMBERVALUE(SUBSTITUTE(VLOOKUP(TEXT(A7,"#"),'EXCEL SMX'!B:Q,9,0),",",".")),"0")*E7 -> 402.84 | G7: =IFERROR(_xlfn.NUMBERVALUE(SUBSTITUTE(VLOOKUP(TEXT(A7,"#"),'EXCEL SMX'!B:Q,16,0),",","."))/100,"0")*F7 -> 0 | H7: =F7-G7 -> 402.84
A8: 7861033001388 | B8: Q. FRESCO BEG 700 GR (UN) | C8: =+IFERROR(VLOOKUP(TEXT(A8,"#"),'EXCEL SMX'!B:I,8,0),0) -> 0018 | D8: =IFERROR(VLOOKUP(TEXT(A8,"#"),'EXCEL SMX'!B:S,18,0),0) -> 000018 | E8: =C8*D8 -> 324 | F8: =IFERROR(_xlfn.NUMBERVALUE(SUBSTITUTE(VLOOKUP(TEXT(A8,"#"),'EXCEL SMX'!B:Q,9,0),",",".")),"0")*E8 -> 1752.84 | G8: =IFERROR(_xlfn.NUMBERVALUE(SUBSTITUTE(VLOOKUP(TEXT(A8,"#"),'EXCEL SMX'!B:Q,16,0),",","."))/100,"0")*F8 -> 350.568 | H8: =F8-G8 -> 1402.272
A9: 7861033000527 | B9: Q. MANABA 400 GR (UN) | C9: =+IFERROR(VLOOKUP(TEXT(A9,"#"),'EXCEL SMX'!B:I,8,0),0) -> 0018 | D9: =IFERROR(VLOOKUP(TEXT(A9,"#"),'EXCEL SMX'!B:S,18,0),0) -> 000012 | E9: =C9*D9 -> 216 | F9: =IFERROR(_xlfn.NUMBERVALUE(SUBSTITUTE(VLOOKUP(TEXT(A9,"#"),'EXCEL SMX'!B:Q,9,0),",",".")),"0")*E9 -> 697.68 | G9: =IFERROR(_xlfn.NUMBERVALUE(SUBSTITUTE(VLOOKUP(TEXT(A9,"#"),'EXCEL SMX'!B:Q,16,0),",","."))/100,"0")*F9 -> 0 | H9: =F9-G9 -> 697.68
A10: 7861033000145 | B10: Q. TIERNO 480 GR (UN) | C10: =+IFERROR(VLOOKUP(TEXT(A10,"#"),'EXCEL SMX'!B:I,8,0),0) -> 0 | D10: =IFERROR(VLOOKUP(TEXT(A10,"#"),'EXCEL SMX'!B:S,18,0),0) -> 0 | E10: =C10*D10 -> 0 | F10: =IFERROR(_xlfn.NUMBERVALUE(SUBSTITUTE(VLOOKUP(TEXT(A10,"#"),'EXCEL SMX'!B:Q,9,0),",",".")),"0")*E10 -> 0 | G10: =IFERROR(_xlfn.NUMBERVALUE(SUBSTITUTE(VLOOKUP(TEXT(A10,"#"),'EXCEL SMX'!B:Q,16,0),",","."))/100,"0")*F10 -> 0 | H10: =F10-G10 -> 0
A11: 7861033000855 | B11: Q. FRESCO DESLACT 450 GR (UN) | C11: =+IFERROR(VLOOKUP(TEXT(A11,"#"),'EXCEL SMX'!B:I,8,0),0) -> 0012 | D11: =IFERROR(VLOOKUP(TEXT(A11,"#"),'EXCEL SMX'!B:S,18,0),0) -> 000010 | E11: =C11*D11 -> 120 | F11: =IFERROR(_xlfn.NUMBERVALUE(SUBSTITUTE(VLOOKUP(TEXT(A11,"#"),'EXCEL SMX'!B:Q,9,0),",",".")),"0")*E11 -> 458.4 | G11: =IFERROR(_xlfn.NUMBERVALUE(SUBSTITUTE(VLOOKUP(TEXT(A11,"#"),'EXCEL SMX'!B:Q,16,0),",","."))/100,"0")*F11 -> 0 | H11: =F11-G11 -> 458.4
A12: 7861033001029 | B12: Q. MOZZ 200 GR (UN) | C12: =+IFERROR(VLOOKUP(TEXT(A12,"#"),'EXCEL SMX'!B:I,8,0),0) -> 0012 | D12: =IFERROR(VLOOKUP(TEXT(A12,"#"),'EXCEL SMX'!B:S,18,0),0) -> 000014 | E12: =C12*D12 -> 168 | F12: =IFERROR(_xlfn.NUMBERVALUE(SUBSTITUTE(VLOOKUP(TEXT(A12,"#"),'EXCEL SMX'!B:Q,9,0),",",".")),"0")*E12 -> 327.6 | G12: =IFERROR(_xlfn.NUMBERVALUE(SUBSTITUTE(VLOOKUP(TEXT(A12,"#"),'EXCEL SMX'!B:Q,16,0),",","."))/100,"0")*F12 -> 0 | H12: =F12-G12 -> 327.6
A13: 7861033000022 | B13: Q. MOZZ 500 GR REDONDO (UN) | C13: =+IFERROR(VLOOKUP(TEXT(A13,"#"),'EXCEL SMX'!B:I,8,0),0) -> 0012 | D13: =IFERROR(VLOOKUP(TEXT(A13,"#"),'EXCEL SMX'!B:S,18,0),0) -> 000058 | E13: =C13*D13 -> 696 | F13: =IFERROR(_xlfn.NUMBERVALUE(SUBSTITUTE(VLOOKUP(TEXT(A13,"#"),'EXCEL SMX'!B:Q,9,0),",",".")),"0")*E13 -> 2923.2 | G13: =IFERROR(_xlfn.NUMBERVALUE(SUBSTITUTE(VLOOKUP(TEXT(A13,"#"),'EXCEL SMX'!B:Q,16,0),",","."))/100,"0")*F13 -> 584.64 | H13: =F13-G13 -> 2338.56
A14: 7861033000077 | B14: Q. MOZZ 700 GR (UN) | C14: =+IFERROR(VLOOKUP(TEXT(A14,"#"),'EXCEL SMX'!B:I,8,0),0) -> 0018 | D14: =IFERROR(VLOOKUP(TEXT(A14,"#"),'EXCEL SMX'!B:S,18,0),0) -> 000004 | E14: =C14*D14 -> 72 | F14: =IFERROR(_xlfn.NUMBERVALUE(SUBSTITUTE(VLOOKUP(TEXT(A14,"#"),'EXCEL SMX'!B:Q,9,0),",",".")),"0")*E14 -> 411.84 | G14: =IFERROR(_xlfn.NUMBERVALUE(SUBSTITUTE(VLOOKUP(TEXT(A14,"#"),'EXCEL SMX'!B:Q,16,0),",","."))/100,"0")*F14 -> 0 | H14: =F14-G14 -> 411.84
A15: 7861033001036 | B15: Q. MOZZ BEG 200 GR (UN) | C15: =+IFERROR(VLOOKUP(TEXT(A15,"#"),'EXCEL SMX'!B:I,8,0),0) -> 0012 | D15: =IFERROR(VLOOKUP(TEXT(A15,"#"),'EXCEL SMX'!B:S,18,0),0) -> 000019 | E15: =C15*D15 -> 228 | F15: =IFERROR(_xlfn.NUMBERVALUE(SUBSTITUTE(VLOOKUP(TEXT(A15,"#"),'EXCEL SMX'!B:Q,9,0),",",".")),"0")*E15 -> 467.4 | G15: =IFERROR(_xlfn.NUMBERVALUE(SUBSTITUTE(VLOOKUP(TEXT(A15,"#"),'EXCEL SMX'!B:Q,16,0),",","."))/100,"0")*F15 -> 0 | H15: =F15-G15 -> 467.4
A16: 7861033000213 | B16: Q. MOZZ BEG 500 GR (UN) | C16: =+IFERROR(VLOOKUP(TEXT(A16,"#"),'EXCEL SMX'!B:I,8,0),0) -> 0018 | D16: =IFERROR(VLOOKUP(TEXT(A16,"#"),'EXCEL SMX'!B:S,18,0),0) -> 000008 | E16: =C16*D16 -> 144 | F16: =IFERROR(_xlfn.NUMBERVALUE(SUBSTITUTE(VLOOKUP(TEXT(A16,"#"),'EXCEL SMX'!B:Q,9,0),",",".")),"0")*E16 -> 665.28 | G16: =IFERROR(_xlfn.NUMBERVALUE(SUBSTITUTE(VLOOKUP(TEXT(A16,"#"),'EXCEL SMX'!B:Q,16,0),",","."))/100,"0")*F16 -> 0 | H16: =F16-G16 -> 665.28
A17: 7861033001081 | B17: Q. MOZZ BEG 700 GR (UN) | C17: =+IFERROR(VLOOKUP(TEXT(A17,"#"),'EXCEL SMX'!B:I,8,0),0) -> 0018 | D17: =IFERROR(VLOOKUP(TEXT(A17,"#"),'EXCEL SMX'!B:S,18,0),0) -> 000014 | E17: =C17*D17 -> 252 | F17: =IFERROR(_xlfn.NUMBERVALUE(SUBSTITUTE(VLOOKUP(TEXT(A17,"#"),'EXCEL SMX'!B:Q,9,0),",",".")),"0")*E17 -> 1575 | G17: =IFERROR(_xlfn.NUMBERVALUE(SUBSTITUTE(VLOOKUP(TEXT(A17,"#"),'EXCEL SMX'!B:Q,16,0),",","."))/100,"0")*F17 -> 315 | H17: =F17-G17 -> 1260
... A34: 7861033001616 | B34: Q. GOUDA 300 GR (UN) | C34: =+IFERROR(VLOOKUP(TEXT(A34,"#"),'EXCEL SMX'!B:I,8,0),0) -> 0 | D34: =IFERROR(VLOOKUP(TEXT(A34,"#"),'EXCEL SMX'!B:S,18,0),0) -> 0 | E34: =C34*D34 -> 0 | F34: =IFERROR(_xlfn.NUMBERVALUE(SUBSTITUTE(VLOOKUP(TEXT(A34,"#"),'EXCEL SMX'!B:Q,9,0),",",".")),"0")*E34 -> 0 | G34: =IFERROR(_xlfn.NUMBERVALUE(SUBSTITUTE(VLOOKUP(TEXT(A34,"#"),'EXCEL SMX'!B:Q,16,0),",","."))/100,"0")*F34 -> 0 | H34: =F34-G34 -> 0
A35: 7861033002163 | B35: Q. GOUDA REB 200 GR (UN) | C35: =+IFERROR(VLOOKUP(TEXT(A35,"#"),'EXCEL SMX'!B:I,8,0),0) -> 0 | D35: =IFERROR(VLOOKUP(TEXT(A35,"#"),'EXCEL SMX'!B:S,18,0),0) -> 0 | E35: =C35*D35 -> 0 | F35: =IFERROR(_xlfn.NUMBERVALUE(SUBSTITUTE(VLOOKUP(TEXT(A35,"#"),'EXCEL SMX'!B:Q,9,0),",",".")),"0")*E35 -> 0 | G35: =IFERROR(_xlfn.NUMBERVALUE(SUBSTITUTE(VLOOKUP(TEXT(A35,"#"),'EXCEL SMX'!B:Q,16,0),",","."))/100,"0")*F35 -> 0 | H35: =F35-G35 -> 0
A36: 7861033000626 | B36: Q. HOLANDES Reb 200 GR (UN) | C36: =+IFERROR(VLOOKUP(TEXT(A36,"#"),'EXCEL SMX'!B:I,8,0),0) -> 0024 | D36: =IFERROR(VLOOKUP(TEXT(A36,"#"),'EXCEL SMX'!B:S,18,0),0) -> 000007 | E36: =C36*D36 -> 168 | F36: =IFERROR(_xlfn.NUMBERVALUE(SUBSTITUTE(VLOOKUP(TEXT(A36,"#"),'EXCEL SMX'!B:Q,9,0),",",".")),"0")*E36 -> 470.4 | G36: =IFERROR(_xlfn.NUMBERVALUE(SUBSTITUTE(VLOOKUP(TEXT(A36,"#"),'EXCEL SMX'!B:Q,16,0),",","."))/100,"0")*F36 -> 94.08 | H36: =F36-G36 -> 376.32
A37: 7861033000633 | B37: Q. HOLANDES Reb 400 GR (UN) | C37: =+IFERROR(VLOOKUP(TEXT(A37,"#"),'EXCEL SMX'!B:I,8,0),0) -> 0012 | D37: =IFERROR(VLOOKUP(TEXT(A37,"#"),'EXCEL SMX'!B:S,18,0),0) -> 000006 | E37: =C37*D37 -> 72 | F37: =IFERROR(_xlfn.NUMBERVALUE(SUBSTITUTE(VLOOKUP(TEXT(A37,"#"),'EXCEL SMX'!B:Q,9,0),",",".")),"0")*E37 -> 388.8 | G37: =IFERROR(_xlfn.NUMBERVALUE(SUBSTITUTE(VLOOKUP(TEXT(A37,"#"),'EXCEL SMX'!B:Q,16,0),",","."))/100,"0")*F37 -> 0 | H37: =F37-G37 -> 388.8
A38: 7861033001432 | B38: Q. HOLANDES Reb 700 GR (UN) | C38: =+IFERROR(VLOOKUP(TEXT(A38,"#"),'EXCEL SMX'!B:I,8,0),0) -> 0 | D38: =IFERROR(VLOOKUP(TEXT(A38,"#"),'EXCEL SMX'!B:S,18,0),0) -> 0 | E38: =C38*D38 -> 0 | F38: =IFERROR(_xlfn.NUMBERVALUE(SUBSTITUTE(VLOOKUP(TEXT(A38,"#"),'EXCEL SMX'!B:Q,9,0),",",".")),"0")*E38 -> 0 | G38: =IFERROR(_xlfn.NUMBERVALUE(SUBSTITUTE(VLOOKUP(TEXT(A38,"#"),'EXCEL SMX'!B:Q,16,0),",","."))/100,"0")*F38 -> 0 | H38: =F38-G38 -> 0
A39: 7861033001449 | B39: Q. MIX CHE Y HOL Reb 700 GR (UN) | C39: =+IFERROR(VLOOKUP(TEXT(A39,"#"),'EXCEL SMX'!B:I,8,0),0) -> 0 | D39: =IFERROR(VLOOKUP(TEXT(A39,"#"),'EXCEL SMX'!B:S,18,0),0) -> 0 | E39: =C39*D39 -> 0 | F39: =IFERROR(_xlfn.NUMBERVALUE(SUBSTITUTE(VLOOKUP(TEXT(A39,"#"),'EXCEL SMX'!B:Q,9,0),",",".")),"0")*E39 -> 0 | G39: =IFERROR(_xlfn.NUMBERVALUE(SUBSTITUTE(VLOOKUP(TEXT(A39,"#"),'EXCEL SMX'!B:Q,16,0),",","."))/100,"0")*F39 -> 0 | H39: =F39-G39 -> 0
A40: 7861033000770 | B40: Q. CHEDDAR Reb BEG 300 GR (UN) | C40: =+IFERROR(VLOOKUP(TEXT(A40,"#"),'EXCEL SMX'!B:I,8,0),0) -> 0 | D40: =IFERROR(VLOOKUP(TEXT(A40,"#"),'EXCEL SMX'!B:S,18,0),0) -> 0 | E40: =C40*D40 -> 0 | F40: =IFERROR(_xlfn.NUMBERVALUE(SUBSTITUTE(VLOOKUP(TEXT(A40,"#"),'EXCEL SMX'!B:Q,9,0),",",".")),"0")*E40 -> 0 | G40: =IFERROR(_xlfn.NUMBERVALUE(SUBSTITUTE(VLOOKUP(TEXT(A40,"#"),'EXCEL SMX'!B:Q,16,0),",","."))/100,"0")*F40 -> 0 | H40: =F40-G40 -> 0
A41: 7861033000794 | B41: Q. HOLANDES Reb BEG 300 GR (UN) | C41: =+IFERROR(VLOOKUP(TEXT(A41,"#"),'EXCEL SMX'!B:I,8,0),0) -> 0 | D41: =IFERROR(VLOOKUP(TEXT(A41,"#"),'EXCEL SMX'!B:S,18,0),0) -> 0 | E41: =C41*D41 -> 0 | F41: =IFERROR(_xlfn.NUMBERVALUE(SUBSTITUTE(VLOOKUP(TEXT(A41,"#"),'EXCEL SMX'!B:Q,9,0),",",".")),"0")*E41 -> 0 | G41: =IFERROR(_xlfn.NUMBERVALUE(SUBSTITUTE(VLOOKUP(TEXT(A41,"#"),'EXCEL SMX'!B:Q,16,0),",","."))/100,"0")*F41 -> 0 | H41: =F41-G41 -> 0
A42: 7861033001098 | B42: Q. HOLANDES Reb DESLACT 200 GR (UN) | C42: =+IFERROR(VLOOKUP(TEXT(A42,"#"),'EXCEL SMX'!B:I,8,0),0) -> 0 | D42: =IFERROR(VLOOKUP(TEXT(A42,"#"),'EXCEL SMX'!B:S,18,0),0) -> 0 | E42: =C42*D42 -> 0 | F42: =IFERROR(_xlfn.NUMBERVALUE(SUBSTITUTE(VLOOKUP(TEXT(A42,"#"),'EXCEL SMX'!B:Q,9,0),",",".")),"0")*E42 -> 0 | G42: =IFERROR(_xlfn.NUMBERVALUE(SUBSTITUTE(VLOOKUP(TEXT(A42,"#"),'EXCEL SMX'!B:Q,16,0),",","."))/100,"0")*F42 -> 0 | H42: =F42-G42 -> 0
A43: 7861033001104 | B43: Q. CHEDDAR Reb DESLACT 200 GR (UN) | C43: =+IFERROR(VLOOKUP(TEXT(A43,"#"),'EXCEL SMX'!B:I,8,0),0) -> 0 | D43: =IFERROR(VLOOKUP(TEXT(A43,"#"),'EXCEL SMX'!B:S,18,0),0) -> 0 | E43: =C43*D43 -> 0 | F43: =IFERROR(_xlfn.NUMBERVALUE(SUBSTITUTE(VLOOKUP(TEXT(A43,"#"),'EXCEL SMX'!B:Q,9,0),",",".")),"0")*E43 -> 0 | G43: =IFERROR(_xlfn.NUMBERVALUE(SUBSTITUTE(VLOOKUP(TEXT(A43,"#"),'EXCEL SMX'!B:Q,16,0),",","."))/100,"0")*F43 -> 0 | H43: =F43-G43 -> 0
A44: 7861033001234 | B44: Q. HOLANDES BEG Bloq 400 GR (UN) | C44: =+IFERROR(VLOOKUP(TEXT(A44,"#"),'EXCEL SMX'!B:I,8,0),0) -> 0 | D44: =IFERROR(VLOOKUP(TEXT(A44,"#"),'EXCEL SMX'!B:S,18,0),0) -> 0 | E44: =C44*D44 -> 0 | F44: =IFERROR(_xlfn.NUMBERVALUE(SUBSTITUTE(VLOOKUP(TEXT(A44,"#"),'EXCEL SMX'!B:Q,9,0),",",".")),"0")*E44 -> 0 | G44: =IFERROR(_xlfn.NUMBERVALUE(SUBSTITUTE(VLOOKUP(TEXT(A44,"#"),'EXCEL SMX'!B:Q,16,0),",","."))/100,"0")*F44 -> 0 | H44: =F44-G44 -> 0
A45: 7861033000640 | B45: Q. CHEDDAR Reb 200 GR (UN) | C45: =+IFERROR(VLOOKUP(TEXT(A45,"#"),'EXCEL SMX'!B:I,8,0),0) -> 0024 | D45: =IFERROR(VLOOKUP(TEXT(A45,"#"),'EXCEL SMX'!B:S,18,0),0) -> 000005 | E45: =C45*D45 -> 120 | F45: =IFERROR(_xlfn.NUMBERVALUE(SUBSTITUTE(VLOOKUP(TEXT(A45,"#"),'EXCEL SMX'!B:Q,9,0),",",".")),"0")*E45 -> 334.8 | G45: =IFERROR(_xlfn.NUMBERVALUE(SUBSTITUTE(VLOOKUP(TEXT(A45,"#"),'EXCEL SMX'!B:Q,16,0),",","."))/100,"0")*F45 -> 0 | H45: =F45-G45 -> 334.8
A46: 7861033001562 | B46: C. AGRIA 200 GR (UN) | C46: =+IFERROR(VLOOKUP(TEXT(A46,"#"),'EXCEL SMX'!B:I,8,0),0) -> 0 | D46: =IFERROR(VLOOKUP(TEXT(A46,"#"),'EXCEL SMX'!B:S,18,0),0) -> 0 | E46: =C46*D46 -> 0 | F46: =IFERROR(_xlfn.NUMBERVALUE(SUBSTITUTE(VLOOKUP(TEXT(A46,"#"),'EXCEL SMX'!B:Q,9,0),",",".")),"0")*E46 -> 0 | G46: =IFERROR(_xlfn.NUMBERVALUE(SUBSTITUTE(VLOOKUP(TEXT(A46,"#"),'EXCEL SMX'!B:Q,16,0),",","."))/100,"0")*F46 -> 0 | H46: =F46-G46 -> 0
A47: 7861033001579 | B47: CREMA 450 GR (UN) | C47: =+IFERROR(VLOOKUP(TEXT(A47,"#"),'EXCEL SMX'!B:I,8,0),0) -> 0 | D47: =IFERROR(VLOOKUP(TEXT(A47,"#"),'EXCEL SMX'!B:S,18,0),0) -> 0 | E47: =C47*D47 -> 0 | F47: =IFERROR(_xlfn.NUMBERVALUE(SUBSTITUTE(VLOOKUP(TEXT(A47,"#"),'EXCEL SMX'!B:Q,9,0),",",".")),"0")*E47 -> 0 | G47: =IFERROR(_xlfn.NUMBERVALUE(SUBSTITUTE(VLOOKUP(TEXT(A47,"#"),'EXCEL SMX'!B:Q,16,0),",","."))/100,"0")*F47 -> 0 | H47: =F47-G47 -> 0
... A60: 7861033001838 | B60: CREMA LECHE SIN LACTOSA 200GR | C60: =+IFERROR(VLOOKUP(TEXT(A60,"#"),'EXCEL SMX'!B:I,8,0),0) -> 0 | D60: =IFERROR(VLOOKUP(TEXT(A60,"#"),'EXCEL SMX'!B:S,18,0),0) -> 0 | E60: =C60*D60 -> 0 | F60: =IFERROR(_xlfn.NUMBERVALUE(SUBSTITUTE(VLOOKUP(TEXT(A60,"#"),'EXCEL SMX'!B:Q,9,0),",",".")),"0")*E60 -> 0 | G60: =IFERROR(_xlfn.NUMBERVALUE(SUBSTITUTE(VLOOKUP(TEXT(A60,"#"),'EXCEL SMX'!B:Q,16,0),",","."))/100,"0")*F60 -> 0 | H60: =F60-G60 -> 0
A61: 7861033003078 | B61: CREMA DE LECHE 250 GR | C61: =+IFERROR(VLOOKUP(TEXT(A61,"#"),'EXCEL SMX'!B:I,8,0),0) -> 0012 | D61: =IFERROR(VLOOKUP(TEXT(A61,"#"),'EXCEL SMX'!B:S,18,0),0) -> 000008 | E61: =C61*D61 -> 96 | F61: =IFERROR(_xlfn.NUMBERVALUE(SUBSTITUTE(VLOOKUP(TEXT(A61,"#"),'EXCEL SMX'!B:Q,9,0),",",".")),"0")*E61 -> 76.8 | G61: =IFERROR(_xlfn.NUMBERVALUE(SUBSTITUTE(VLOOKUP(TEXT(A61,"#"),'EXCEL SMX'!B:Q,16,0),",","."))/100,"0")*F61 -> 0 | H61: =F61-G61 -> 76.8
A62: 7861033003085 | B62: CREMA DE LECHE 500 GR | C62: =+IFERROR(VLOOKUP(TEXT(A62,"#"),'EXCEL SMX'!B:I,8,0),0) -> 0012 | D62: =IFERROR(VLOOKUP(TEXT(A62,"#"),'EXCEL SMX'!B:S,18,0),0) -> 000004 | E62: =C62*D62 -> 48 | F62: =IFERROR(_xlfn.NUMBERVALUE(SUBSTITUTE(VLOOKUP(TEXT(A62,"#"),'EXCEL SMX'!B:Q,9,0),",",".")),"0")*E62 -> 69.6 | G62: =IFERROR(_xlfn.NUMBERVALUE(SUBSTITUTE(VLOOKUP(TEXT(A62,"#"),'EXCEL SMX'!B:Q,16,0),",","."))/100,"0")*F62 -> 13.92 | H62: =F62-G62 -> 55.68
A63: 7861033003092 | B63: CREMA DE LECHE 900 GR | C63: =+IFERROR(VLOOKUP(TEXT(A63,"#"),'EXCEL SMX'!B:I,8,0),0) -> 0012 | D63: =IFERROR(VLOOKUP(TEXT(A63,"#"),'EXCEL SMX'!B:S,18,0),0) -> 000006 | E63: =C63*D63 -> 72 | F63: =IFERROR(_xlfn.NUMBERVALUE(SUBSTITUTE(VLOOKUP(TEXT(A63,"#"),'EXCEL SMX'!B:Q,9,0),",",".")),"0")*E63 -> 172.8 | G63: =IFERROR(_xlfn.NUMBERVALUE(SUBSTITUTE(VLOOKUP(TEXT(A63,"#"),'EXCEL SMX'!B:Q,16,0),",","."))/100,"0")*F63 -> 34.56 | H63: =F63-G63 -> 138.24
A64: 7861033001975 | B64: SAN ENRIQUE Q.FRESCO CREMOSO | C64: =+IFERROR(VLOOKUP(TEXT(A64,"#"),'EXCEL SMX'!B:I,8,0),0) -> 0 | D64: =IFERROR(VLOOKUP(TEXT(A64,"#"),'EXCEL SMX'!B:S,18,0),0) -> 0 | E64: =C64*D64 -> 0 | F64: =IFERROR(_xlfn.NUMBERVALUE(SUBSTITUTE(VLOOKUP(TEXT(A64,"#"),'EXCEL SMX'!B:Q,9,0),",",".")),"0")*E64 -> 0 | G64: =IFERROR(_xlfn.NUMBERVALUE(SUBSTITUTE(VLOOKUP(TEXT(A64,"#"),'EXCEL SMX'!B:Q,16,0),",","."))/100,"0")*F64 -> 0 | H64: =F64-G64 -> 0
A65: 7861033002019 | B65: SAN ENRIQUE Q.MOZZARELLA | C65: =+IFERROR(VLOOKUP(TEXT(A65,"#"),'EXCEL SMX'!B:I,8,0),0) -> 0 | D65: =IFERROR(VLOOKUP(TEXT(A65,"#"),'EXCEL SMX'!B:S,18,0),0) -> 0 | E65: =C65*D65 -> 0 | F65: =IFERROR(_xlfn.NUMBERVALUE(SUBSTITUTE(VLOOKUP(TEXT(A65,"#"),'EXCEL SMX'!B:Q,9,0),",",".")),"0")*E65 -> 0 | G65: =IFERROR(_xlfn.NUMBERVALUE(SUBSTITUTE(VLOOKUP(TEXT(A65,"#"),'EXCEL SMX'!B:Q,16,0),",","."))/100,"0")*F65 -> 0 | H65: =F65-G65 -> 0
A66: 7861033002033 | B66: SAN ENRIQUE Q.MOZZARELLA BAJO | C66: =+IFERROR(VLOOKUP(TEXT(A66,"#"),'EXCEL SMX'!B:I,8,0),0) -> 0 | D66: =IFERROR(VLOOKUP(TEXT(A66,"#"),'EXCEL SMX'!B:S,18,0),0) -> 0 | E66: =C66*D66 -> 0 | F66: =IFERROR(_xlfn.NUMBERVALUE(SUBSTITUTE(VLOOKUP(TEXT(A66,"#"),'EXCEL SMX'!B:Q,9,0),",",".")),"0")*E66 -> 0 | G66: =IFERROR(_xlfn.NUMBERVALUE(SUBSTITUTE(VLOOKUP(TEXT(A66,"#"),'EXCEL SMX'!B:Q,16,0),",","."))/100,"0")*F66 -> 0 | H66: =F66-G66 -> 0
A67: 7861033002071 | B67: SAN ENRIQUE Q HOLANDES REBANAD | C67: =+IFERROR(VLOOKUP(TEXT(A67,"#"),'EXCEL SMX'!B:I,8,0),0) -> 0 | D67: =IFERROR(VLOOKUP(TEXT(A67,"#"),'EXCEL SMX'!B:S,18,0),0) -> 0 | E67: =C67*D67 -> 0 | F67: =IFERROR(_xlfn.NUMBERVALUE(SUBSTITUTE(VLOOKUP(TEXT(A67,"#"),'EXCEL SMX'!B:Q,9,0),",",".")),"0")*E67 -> 0 | G67: =IFERROR(_xlfn.NUMBERVALUE(SUBSTITUTE(VLOOKUP(TEXT(A67,"#"),'EXCEL SMX'!B:Q,16,0),",","."))/100,"0")*F67 -> 0 | H67: =F67-G67 -> 0
A68: 7861033002156 | B68: SAN ENRIQUE CREMA AGRIA | C68: =+IFERROR(VLOOKUP(TEXT(A68,"#"),'EXCEL SMX'!B:I,8,0),0) -> 0 | D68: =IFERROR(VLOOKUP(TEXT(A68,"#"),'EXCEL SMX'!B:S,18,0),0) -> 0 | E68: =C68*D68 -> 0 | F68: =IFERROR(_xlfn.NUMBERVALUE(SUBSTITUTE(VLOOKUP(TEXT(A68,"#"),'EXCEL SMX'!B:Q,9,0),",",".")),"0")*E68 -> 0 | G68: =IFERROR(_xlfn.NUMBERVALUE(SUBSTITUTE(VLOOKUP(TEXT(A68,"#"),'EXCEL SMX'!B:Q,16,0),",","."))/100,"0")*F68 -> 0 | H68: =F68-G68 -> 0
...

Sheet FINAL AE
A1: COD. | B1: FAM | C1: PRODUCTO | D1: UND | E1: # CAJAS | F1: UNIDAD | G1: VALOR | H1: DESCTO. | I1: USD | J1: IVA
A2: 7861033001630 | B2: AME | C2: AME REB 200G | D2: =_xlfn.NUMBERVALUE(IFERROR(VLOOKUP(TEXT(A2,"#"),'EXCEL SMX'!B:I,8,0),0)) -> 0 | E2: =_xlfn.NUMBERVALUE(VLOOKUP(A2,'FINAL BODEGA'!A:D,4,0)) -> 0 | F2: =D2*E2 -> 0 | G2: =IFERROR(_xlfn.NUMBERVALUE(SUBSTITUTE(VLOOKUP(TEXT(A2,"#"),'EXCEL SMX'!B:Q,9,0),",",".")),"0")*F2 -> 0 | H2: =IFERROR(_xlfn.NUMBERVALUE(SUBSTITUTE(VLOOKUP(TEXT(A2,"#"),'EXCEL SMX'!B:Q,16,0),",","."))/100,"0")*G2 -> 0 | I2: =G2-H2 -> 0
A3: 7861033001784 | B3: AME | C3: AME REB 400G | D3: =_xlfn.NUMBERVALUE(IFERROR(VLOOKUP(TEXT(A3,"#"),'EXCEL SMX'!B:I,8,0),0)) -> 0 | E3: =_xlfn.NUMBERVALUE(VLOOKUP(A3,'FINAL BODEGA'!A:D,4,0)) -> 0 | F3: =D3*E3 -> 0 | G3: =IFERROR(_xlfn.NUMBERVALUE(SUBSTITUTE(VLOOKUP(TEXT(A3,"#"),'EXCEL SMX'!B:Q,9,0),",",".")),"0")*F3 -> 0 | H3: =IFERROR(_xlfn.NUMBERVALUE(SUBSTITUTE(VLOOKUP(TEXT(A3,"#"),'EXCEL SMX'!B:Q,16,0),",","."))/100,"0")*G3 -> 0 | I3: =G3-H3 -> 0
A4: 7861033001609 | B4: AND | C4: ANDINO 375G | D4: =_xlfn.NUMBERVALUE(IFERROR(VLOOKUP(TEXT(A4,"#"),'EXCEL SMX'!B:I,8,0),0)) -> 0 | E4: =_xlfn.NUMBERVALUE(VLOOKUP(A4,'FINAL BODEGA'!A:D,4,0)) -> 0 | F4: =D4*E4 -> 0 | G4: =IFERROR(_xlfn.NUMBERVALUE(SUBSTITUTE(VLOOKUP(TEXT(A4,"#"),'EXCEL SMX'!B:Q,9,0),",",".")),"0")*F4 -> 0 | H4: =IFERROR(_xlfn.NUMBERVALUE(SUBSTITUTE(VLOOKUP(TEXT(A4,"#"),'EXCEL SMX'!B:Q,16,0),",","."))/100,"0")*G4 -> 0 | I4: =G4-H4 -> 0
A5: 7861033001791 | B5: AND | C5: ANDINO 700G | D5: =_xlfn.NUMBERVALUE(IFERROR(VLOOKUP(TEXT(A5,"#"),'EXCEL SMX'!B:I,8,0),0)) -> 0 | E5: =_xlfn.NUMBERVALUE(VLOOKUP(A5,'FINAL BODEGA'!A:D,4,0)) -> 0 | F5: =D5*E5 -> 0 | G5: =IFERROR(_xlfn.NUMBERVALUE(SUBSTITUTE(VLOOKUP(TEXT(A5,"#"),'EXCEL SMX'!B:Q,9,0),",",".")),"0")*F5 -> 0 | H5: =IFERROR(_xlfn.NUMBERVALUE(SUBSTITUTE(VLOOKUP(TEXT(A5,"#"),'EXCEL SMX'!B:Q,16,0),",","."))/100,"0")*G5 -> 0 | I5: =G5-H5 -> 0
A6: 7861033001241 | B6: CHBG | C6: CHE BEG 200G | D6: =_xlfn.NUMBERVALUE(IFERROR(VLOOKUP(TEXT(A6,"#"),'EXCEL SMX'!B:I,8,0),0)) -> 0 | E6: =_xlfn.NUMBERVALUE(VLOOKUP(A6,'FINAL BODEGA'!A:D,4,0)) -> 0 | F6: =D6*E6 -> 0 | G6: =IFERROR(_xlfn.NUMBERVALUE(SUBSTITUTE(VLOOKUP(TEXT(A6,"#"),'EXCEL SMX'!B:Q,9,0),",",".")),"0")*F6 -> 0 | H6: =IFERROR(_xlfn.NUMBERVALUE(SUBSTITUTE(VLOOKUP(TEXT(A6,"#"),'EXCEL SMX'!B:Q,16,0),",","."))/100,"0")*G6 -> 0 | I6: =G6-H6 -> 0
A7: 7861033000770 | B7: CHBG | C7: CHE REB BEG 300G | D7: =_xlfn.NUMBERVALUE(IFERROR(VLOOKUP(TEXT(A7,"#"),'EXCEL SMX'!B:I,8,0),0)) -> 0 | E7: =_xlfn.NUMBERVALUE(VLOOKUP(A7,'FINAL BODEGA'!A:D,4,0)) -> 0 | F7: =D7*E7 -> 0 | G7: =IFERROR(_xlfn.NUMBERVALUE(SUBSTITUTE(VLOOKUP(TEXT(A7,"#"),'EXCEL SMX'!B:Q,9,0),",",".")),"0")*F7 -> 0 | H7: =IFERROR(_xlfn.NUMBERVALUE(SUBSTITUTE(VLOOKUP(TEXT(A7,"#"),'EXCEL SMX'!B:Q,16,0),",","."))/100,"0")*G7 -> 0 | I7: =G7-H7 -> 0
A8: 7861033001104 | B8: CHBG | C8: CHE REB SL 200G | D8: =_xlfn.NUMBERVALUE(IFERROR(VLOOKUP(TEXT(A8,"#"),'EXCEL SMX'!B:I,8,0),0)) -> 0 | E8: =_xlfn.NUMBERVALUE(VLOOKUP(A8,'FINAL BODEGA'!A:D,4,0)) -> 0 | F8: =D8*E8 -> 0 | G8: =IFERROR(_xlfn.NUMBERVALUE(SUBSTITUTE(VLOOKUP(TEXT(A8,"#"),'EXCEL SMX'!B:Q,9,0),",",".")),"0")*F8 -> 0 | H8: =IFERROR(_xlfn.NUMBERVALUE(SUBSTITUTE(VLOOKUP(TEXT(A8,"#"),'EXCEL SMX'!B:Q,16,0),",","."))/100,"0")*G8 -> 0 | I8: =G8-H8 -> 0
A9: 7861033001289 | B9: CHE | C9: CHE 200G | D9: =_xlfn.NUMBERVALUE(IFERROR(VLOOKUP(TEXT(A9,"#"),'EXCEL SMX'!B:I,8,0),0)) -> 0 | E9: =_xlfn.NUMBERVALUE(VLOOKUP(A9,'FINAL BODEGA'!A:D,4,0)) -> 0 | F9: =D9*E9 -> 0 | G9: =IFERROR(_xlfn.NUMBERVALUE(SUBSTITUTE(VLOOKUP(TEXT(A9,"#"),'EXCEL SMX'!B:Q,9,0),",",".")),"0")*F9 -> 0 | H9: =IFERROR(_xlfn.NUMBERVALUE(SUBSTITUTE(VLOOKUP(TEXT(A9,"#"),'EXCEL SMX'!B:Q,16,0),",","."))/100,"0")*G9 -> 0 | I9: =G9-H9 -> 0
A10: 7861033001814 | B10: CHE | C10: CHE 375G | D10: =_xlfn.NUMBERVALUE(IFERROR(VLOOKUP(TEXT(A10,"#"),'EXCEL SMX'!B:I,8,0),0)) -> 0 | E10: =_xlfn.NUMBERVALUE(VLOOKUP(A10,'FINAL BODEGA'!A:D,4,0)) -> 0 | F10: =D10*E10 -> 0 | G10: =IFERROR(_xlfn.NUMBERVALUE(SUBSTITUTE(VLOOKUP(TEXT(A10,"#"),'EXCEL SMX'!B:Q,9,0),",",".")),"0")*F10 -> 0 | H10: =IFERROR(_xlfn.NUMBERVALUE(SUBSTITUTE(VLOOKUP(TEXT(A10,"#"),'EXCEL SMX'!B:Q,16,0),",","."))/100,"0")*G10 -> 0 | I10: =G10-H10 -> 0
A11: 7861033000640 | B11: CHE | C11: CHE REB 200G | D11: =_xlfn.NUMBERVALUE(IFERROR(VLOOKUP(TEXT(A11,"#"),'EXCEL SMX'!B:I,8,0),0)) -> 24 | E11: =_xlfn.NUMBERVALUE(VLOOKUP(A11,'FINAL BODEGA'!A:D,4,0)) -> 5 | F11: =D11*E11 -> 120 | G11: =IFERROR(_xlfn.NUMBERVALUE(SUBSTITUTE(VLOOKUP(TEXT(A11,"#"),'EXCEL SMX'!B:Q,9,0),",",".")),"0")*F11 -> 334.8 | H11: =IFERROR(_xlfn.NUMBERVALUE(SUBSTITUTE(VLOOKUP(TEXT(A11,"#"),'EXCEL SMX'!B:Q,16,0),",","."))/100,"0")*G11 -> 0 | I11: =G11-H11 -> 334.8
A12: 7861033000657 | B12: CHE | C12: CHE REB 400G | D12: =_xlfn.NUMBERVALUE(IFERROR(VLOOKUP(TEXT(A12,"#"),'EXCEL SMX'!B:I,8,0),0)) -> 12 | E12: =_xlfn.NUMBERVALUE(VLOOKUP(A12,'FINAL BODEGA'!A:D,4,0)) -> 12 | F12: =D12*E12 -> 144 | G12: =IFERROR(_xlfn.NUMBERVALUE(SUBSTITUTE(VLOOKUP(TEXT(A12,"#"),'EXCEL SMX'!B:Q,9,0),",",".")),"0")*F12 -> 777.6 | H12: =IFERROR(_xlfn.NUMBERVALUE(SUBSTITUTE(VLOOKUP(TEXT(A12,"#"),'EXCEL SMX'!B:Q,16,0),",","."))/100,"0")*G12 -> 155.52 | I12: =G12-H12 -> 622.08
A13: 7861033001425 | B13: CHE | C13: CHE REB 700G | D13: =_xlfn.NUMBERVALUE(IFERROR(VLOOKUP(TEXT(A13,"#"),'EXCEL SMX'!B:I,8,0),0)) -> 0 | E13: =_xlfn.NUMBERVALUE(VLOOKUP(A13,'FINAL BODEGA'!A:D,4,0)) -> 0 | F13: =D13*E13 -> 0 | G13: =IFERROR(_xlfn.NUMBERVALUE(SUBSTITUTE(VLOOKUP(TEXT(A13,"#"),'EXCEL SMX'!B:Q,9,0),",",".")),"0")*F13 -> 0 | H13: =IFERROR(_xlfn.NUMBERVALUE(SUBSTITUTE(VLOOKUP(TEXT(A13,"#"),'EXCEL SMX'!B:Q,16,0),",","."))/100,"0")*G13 -> 0 | I13: =G13-H13 -> 0
A14: 7861033001449 | B14: CHE | C14: MIX 700G | D14: =_xlfn.NUMBERVALUE(IFERROR(VLOOKUP(TEXT(A14,"#"),'EXCEL SMX'!B:I,8,0),0)) -> 0 | E14: =_xlfn.NUMBERVALUE(VLOOKUP(A14,'FINAL BODEGA'!A:D,4,0)) -> 0 | F14: =D14*E14 -> 0 | G14: =IFERROR(_xlfn.NUMBERVALUE(SUBSTITUTE(VLOOKUP(TEXT(A14,"#"),'EXCEL SMX'!B:Q,9,0),",",".")),"0")*F14 -> 0 | H14: =IFERROR(_xlfn.NUMBERVALUE(SUBSTITUTE(VLOOKUP(TEXT(A14,"#"),'EXCEL SMX'!B:Q,16,0),",","."))/100,"0")*G14 -> 0 | I14: =G14-H14 -> 0
A15: 7861033001562 | B15: CREM | C15: C. AGRIA 200G | D15: =_xlfn.NUMBERVALUE(IFERROR(VLOOKUP(TEXT(A15,"#"),'EXCEL SMX'!B:I,8,0),0)) -> 0 | E15: =_xlfn.NUMBERVALUE(VLOOKUP(A15,'FINAL BODEGA'!A:D,4,0)) -> 0 | F15: =D15*E15 -> 0 | G15: =IFERROR(_xlfn.NUMBERVALUE(SUBSTITUTE(VLOOKUP(TEXT(A15,"#"),'EXCEL SMX'!B:Q,9,0),",",".")),"0")*F15 -> 0 | H15: =IFERROR(_xlfn.NUMBERVALUE(SUBSTITUTE(VLOOKUP(TEXT(A15,"#"),'EXCEL SMX'!B:Q,16,0),",","."))/100,"0")*G15 -> 0 | I15: =G15-H15 -> 0 | J15: X
A16: 7861033001579 | B16: CREM | C16: CDL 450G | D16: =_xlfn.NUMBERVALUE(IFERROR(VLOOKUP(TEXT(A16,"#"),'EXCEL SMX'!B:I,8,0),0)) -> 0 | E16: =_xlfn.NUMBERVALUE(VLOOKUP(A16,'FINAL BODEGA'!A:D,4,0)) -> 0 | F16: =D16*E16 -> 0 | G16: =IFERROR(_xlfn.NUMBERVALUE(SUBSTITUTE(VLOOKUP(TEXT(A16,"#"),'EXCEL SMX'!B:Q,9,0),",",".")),"0")*F16 -> 0 | H16: =IFERROR(_xlfn.NUMBERVALUE(SUBSTITUTE(VLOOKUP(TEXT(A16,"#"),'EXCEL SMX'!B:Q,16,0),",","."))/100,"0")*G16 -> 0 | I16: =G16-H16 -> 0 | J16: X
A17: 7861033001838 | B17: CREM | C17: CDL SL 200G | D17: =_xlfn.NUMBERVALUE(IFERROR(VLOOKUP(TEXT(A17,"#"),'EXCEL SMX'!B:I,8,0),0)) -> 0 | E17: =_xlfn.NUMBERVALUE(VLOOKUP(A17,'FINAL BODEGA'!A:D,4,0)) -> 0 | F17: =D17*E17 -> 0 | G17: =IFERROR(_xlfn.NUMBERVALUE(SUBSTITUTE(VLOOKUP(TEXT(A17,"#"),'EXCEL SMX'!B:Q,9,0),",",".")),"0")*F17 -> 0 | H17: =IFERROR(_xlfn.NUMBERVALUE(SUBSTITUTE(VLOOKUP(TEXT(A17,"#"),'EXCEL SMX'!B:Q,16,0),",","."))/100,"0")*G17 -> 0 | I17: =G17-H17 -> 0 | J17: X
A18: 7861033003078 | B18: CREM | C18: CREMA DE LECHE 250 GR | D18: =_xlfn.NUMBERVALUE(IFERROR(VLOOKUP(TEXT(A18,"#"),'EXCEL SMX'!B:I,8,0),0)) -> 12 | E18: =_xlfn.NUMBERVALUE(VLOOKUP(A18,'FINAL BODEGA'!A:D,4,0)) -> 8 | F18: =D18*E18 -> 96 | G18: =IFERROR(_xlfn.NUMBERVALUE(SUBSTITUTE(VLOOKUP(TEXT(A18,"#"),'EXCEL SMX'!B:Q,9,0),",",".")),"0")*F18 -> 76.8 | H18: =IFERROR(_xlfn.NUMBERVALUE(SUBSTITUTE(VLOOKUP(TEXT(A18,"#"),'EXCEL SMX'!B:Q,16,0),",","."))/100,"0")*G18 -> 0 | I18: =G18-H18 -> 76.8 | J18: X
A19: 7861033003085 | B19: CREM | C19: CREMA DE LECHE 500GR | D19: =_xlfn.NUMBERVALUE(IFERROR(VLOOKUP(TEXT(A19,"#"),'EXCEL SMX'!B:I,8,0),0)) -> 12 | E19: =_xlfn.NUMBERVALUE(VLOOKUP(A19,'FINAL BODEGA'!A:D,4,0)) -> 4 | F19: =D19*E19 -> 48 | G19: =IFERROR(_xlfn.NUMBERVALUE(SUBSTITUTE(VLOOKUP(TEXT(A19,"#"),'EXCEL SMX'!B:Q,9,0),",",".")),"0")*F19 -> 69.6 | H19: =IFERROR(_xlfn.NUMBERVALUE(SUBSTITUTE(VLOOKUP(TEXT(A19,"#"),'EXCEL SMX'!B:Q,16,0),",","."))/100,"0")*G19 -> 13.92 | I19: =G19-H19 -> 55.68 | J19: X
A20: 7861033003092 | B20: CREM | C20: CREMA DE LECHE 900 GR | D20: =_xlfn.NUMBERVALUE(IFERROR(VLOOKUP(TEXT(A20,"#"),'EXCEL SMX'!B:I,8,0),0)) -> 12 | E20: =_xlfn.NUMBERVALUE(VLOOKUP(A20,'FINAL BODEGA'!A:D,4,0)) -> 6 | F20: =D20*E20 -> 72 | G20: =IFERROR(_xlfn.NUMBERVALUE(SUBSTITUTE(VLOOKUP(TEXT(A20,"#"),'EXCEL SMX'!B:Q,9,0),",",".")),"0")*F20 -> 172.8 | H20: =IFERROR(_xlfn.NUMBERVALUE(SUBSTITUTE(VLOOKUP(TEXT(A20,"#"),'EXCEL SMX'!B:Q,16,0),",","."))/100,"0")*G20 -> 34.56 | I20: =G20-H20 -> 138.24 | J20: X
A21: 7861033002156 | B21: CREM | C21: SE SALSA CREMA 180G | D21: =_xlfn.NUMBERVALUE(IFERROR(VLOOKUP(TEXT(A21,"#"),'EXCEL SMX'!B:I,8,0),0)) -> 0 | E21: =_xlfn.NUMBERVALUE(VLOOKUP(A21,'FINAL BODEGA'!A:D,4,0)) -> 0 | F21: =D21*E21 -> 0 | G21: =IFERROR(_xlfn.NUMBERVALUE(SUBSTITUTE(VLOOKUP(TEXT(A21,"#"),'EXCEL SMX'!B:Q,9,0),",",".")),"0")*F21 -> 0 | H21: =IFERROR(_xlfn.NUMBERVALUE(SUBSTITUTE(VLOOKUP(TEXT(A21,"#"),'EXCEL SMX'!B:Q,16,0),",","."))/100,"0")*G21 -> 0 | I21: =G21-H21 -> 0 | J21: X
A22: 7861033002507 | B22: F | C22: FRESCO 450G | D22: =_xlfn.NUMBERVALUE(IFERROR(VLOOKUP(TEXT(A22,"#"),'EXCEL SMX'!B:I,8,0),0)) -> 12 | E22: =_xlfn.NUMBERVALUE(VLOOKUP(A22,'FINAL BODEGA'!A:D,4,0)) -> 5 | F22: =D22*E22 -> 60 | G22: =IFERROR(_xlfn.NUMBERVALUE(SUBSTITUTE(VLOOKUP(TEXT(A22,"#"),'EXCEL SMX'!B:Q,9,0),",",".")),"0")*F22 -> 192.6 | H22: =IFERROR(_xlfn.NUMBERVALUE(SUBSTITUTE(VLOOKUP(TEXT(A22,"#"),'EXCEL SMX'!B:Q,16,0),",","."))/100,"0")*G22 -> 0 | I22: =G22-H22 -> 192.6
A23: 7861033000312 | B23: F | C23: FRESCO 700G | D23: =_xlfn.NUMBERVALUE(IFERROR(VLOOKUP(TEXT(A23,"#"),'EXCEL SMX'!B:I,8,0),0)) -> 8 | E23: =_xlfn.NUMBERVALUE(VLOOKUP(A23,'FINAL BODEGA'!A:D,4,0)) -> 11 | F23: =D23*E23 -> 88 | G23: =IFERROR(_xlfn.NUMBERVALUE(SUBSTITUTE(VLOOKUP(TEXT(A23,"#"),'EXCEL SMX'!B:Q,9,0),",",".")),"0")*F23 -> 440.88 | H23: =IFERROR(_xlfn.NUMBERVALUE(SUBSTITUTE(VLOOKUP(TEXT(A23,"#"),'EXCEL SMX'!B:Q,16,0),",","."))/100,"0")*G23 -> 0 | I23: =G23-H23 -> 440.88
A24: 7861033001982 | B24: F | C24: SE CREMOSO 650G | D24: =_xlfn.NUMBERVALUE(IFERROR(VLOOKUP(TEXT(A24,"#"),'EXCEL SMX'!B:I,8,0),0)) -> 0 | E24: =_xlfn.NUMBERVALUE(VLOOKUP(A24,'FINAL BODEGA'!A:D,4,0)) -> 0 | F24: =D24*E24 -> 0 | G24: =IFERROR(_xlfn.NUMBERVALUE(SUBSTITUTE(VLOOKUP(TEXT(A24,"#"),'EXCEL SMX'!B:Q,9,0),",",".")),"0")*F24 -> 0 | H24: =IFERROR(_xlfn.NUMBERVALUE(SUBSTITUTE(VLOOKUP(TEXT(A24,"#"),'EXCEL SMX'!B:Q,16,0),",","."))/100,"0")*G24 -> 0 | I24: =G24-H24 -> 0
A25: 7861033000831 | B25: FBG | C25: FRESCO BEG 450G | D25: =_xlfn.NUMBERVALUE(IFERROR(VLOOKUP(TEXT(A25,"#"),'EXCEL SMX'!B:I,8,0),0)) -> 18 | E25: =_xlfn.NUMBERVALUE(VLOOKUP(A25,'FINAL BODEGA'!A:D,4,0)) -> 6 | F25: =D25*E25 -> 108 | G25: =IFERROR(_xlfn.NUMBERVALUE(SUBSTITUTE(VLOOKUP(TEXT(A25,"#"),'EXCEL SMX'!B:Q,9,0),",",".")),"0")*F25 -> 402.84 | H25: =IFERROR(_xlfn.NUMBERVALUE(SUBSTITUTE(VLOOKUP(TEXT(A25,"#"),'EXCEL SMX'!B:Q,16,0),",","."))/100,"0")*G25 -> 0 | I25: =G25-H25 -> 402.84
A26: 7861033001388 | B26: FBG | C26: FRESCO BEG 700G | D26: =_xlfn.NUMBERVALUE(IFERROR(VLOOKUP(TEXT(A26,"#"),'EXCEL SMX'!B:I,8,0),0)) -> 18 | E26: =_xlfn.NUMBERVALUE(VLOOKUP(A26,'FINAL BODEGA'!A:D,4,0)) -> 18 | F26: =D26*E26 -> 324 | G26: =IFERROR(_xlfn.NUMBERVALUE(SUBSTITUTE(VLOOKUP(TEXT(A26,"#"),'EXCEL SMX'!B:Q,9,0),",",".")),"0")*F26 -> 1752.84 | H26: =IFERROR(_xlfn.NUMBERVALUE(SUBSTITUTE(VLOOKUP(TEXT(A26,"#"),'EXCEL SMX'!B:Q,16,0),",","."))/100,"0")*G26 -> 350.568 | I26: =G26-H26 -> 1402.272
A27: 7861033000855 | B27: FBL | C27: FRESCO SL 450G | D27: =_xlfn.NUMBERVALUE(IFERROR(VLOOKUP(TEXT(A27,"#"),'EXCEL SMX'!B:I,8,0),0)) -> 12 | E27: =_xlfn.NUMBERVALUE(VLOOKUP(A27,'FINAL BODEGA'!A:D,4,0)) -> 10 | F27: =D27*E27 -> 120 | G27: =IFERROR(_xlfn.NUMBERVALUE(SUBSTITUTE(VLOOKUP(TEXT(A27,"#"),'EXCEL SMX'!B:Q,9,0),",",".")),"0")*F27 -> 458.4 | H27: =IFERROR(_xlfn.NUMBERVALUE(SUBSTITUTE(VLOOKUP(TEXT(A27,"#"),'EXCEL SMX'!B:Q,16,0),",","."))/100,"0")*G27 -> 0 | I27: =G27-H27 -> 458.4
A28: 7861033000350 | B28: FC | C28: CRIOLLO 400G | D28: =_xlfn.NUMBERVALUE(IFERROR(VLOOKUP(TEXT(A28,"#"),'EXCEL SMX'!B:I,8,0),0)) -> 24 | E28: =_xlfn.NUMBERVALUE(VLOOKUP(A28,'FINAL BODEGA'!A:D,4,0)) -> 3 | F28: =D28*E28 -> 72 | G28: =IFERROR(_xlfn.NUMBERVALUE(SUBSTITUTE(VLOOKUP(TEXT(A28,"#"),'EXCEL SMX'!B:Q,9,0),",",".")),"0")*F28 -> 219.6 | H28: =IFERROR(_xlfn.NUMBERVALUE(SUBSTITUTE(VLOOKUP(TEXT(A28,"#"),'EXCEL SMX'!B:Q,16,0),",","."))/100,"0")*G28 -> 0 | I28: =G28-H28 -> 219.6
A29: 7861033001364 | B29: FC | C29: CRIOLLO 700G | D29: =_xlfn.NUMBERVALUE(IFERROR(VLOOKUP(TEXT(A29,"#"),'EXCEL SMX'!B:I,8,0),0)) -> 18 | E29: =_xlfn.NUMBERVALUE(VLOOKUP(A29,'FINAL BODEGA'!A:D,4,0)) -> 32 | F29: =D29*E29 -> 576 | G29: =IFERROR(_xlfn.NUMBERVALUE(SUBSTITUTE(VLOOKUP(TEXT(A29,"#"),'EXCEL SMX'!B:Q,9,0),",",".")),"0")*F29 -> 2972.16 | H29: =IFERROR(_xlfn.NUMBERVALUE(SUBSTITUTE(VLOOKUP(TEXT(A29,"#"),'EXCEL SMX'!B:Q,16,0),",","."))/100,"0")*G29 -> 594.432 | I29: =G29-H29 -> 2377.728
A30: 7861033001975 | B30: FC | C30: SE CREMOSO 380G | D30: =_xlfn.NUMBERVALUE(IFERROR(VLOOKUP(TEXT(A30,"#"),'EXCEL SMX'!B:I,8,0),0)) -> 0 | E30: =_xlfn.NUMBERVALUE(VLOOKUP(A30,'FINAL BODEGA'!A:D,4,0)) -> 0 | F30: =D30*E30 -> 0 | G30: =IFERROR(_xlfn.NUMBERVALUE(SUBSTITUTE(VLOOKUP(TEXT(A30,"#"),'EXCEL SMX'!B:Q,9,0),",",".")),"0")*F30 -> 0 | H30: =IFERROR(_xlfn.NUMBERVALUE(SUBSTITUTE(VLOOKUP(TEXT(A30,"#"),'EXCEL SMX'!B:Q,16,0),",","."))/100,"0")*G30 -> 0 | I30: =G30-H30 -> 0
A31: 7861033000527 | B31: FM | C31: MANABA 400G | D31: =_xlfn.NUMBERVALUE(IFERROR(VLOOKUP(TEXT(A31,"#"),'EXCEL SMX'!B:I,8,0),0)) -> 18 | E31: =_xlfn.NUMBERVALUE(VLOOKUP(A31,'FINAL BODEGA'!A:D,4,0)) -> 12 | F31: =D31*E31 -> 216 | G31: =IFERROR(_xlfn.NUMBERVALUE(SUBSTITUTE(VLOOKUP(TEXT(A31,"#"),'EXCEL SMX'!B:Q,9,0),",",".")),"0")*F31 -> 697.68 | H31: =IFERROR(_xlfn.NUMBERVALUE(SUBSTITUTE(VLOOKUP(TEXT(A31,"#"),'EXCEL SMX'!B:Q,16,0),",","."))/100,"0")*G31 -> 0 | I31: =G31-H31 -> 697.68
A32: 7861033001371 | B32: FM | C32: MANABA 700G | D32: =_xlfn.NUMBERVALUE(IFERROR(VLOOKUP(TEXT(A32,"#"),'EXCEL SMX'!B:I,8,0),0)) -> 18 | E32: =_xlfn.NUMBERVALUE(VLOOKUP(A32,'FINAL BODEGA'!A:D,4,0)) -> 3 | F32: =D32*E32 -> 54 | G32: =IFERROR(_xlfn.NUMBERVALUE(SUBSTITUTE(VLOOKUP(TEXT(A32,"#"),'EXCEL SMX'!B:Q,9,0),",",".")),"0")*F32 -> 292.14 | H32: =IFERROR(_xlfn.NUMBERVALUE(SUBSTITUTE(VLOOKUP(TEXT(A32,"#"),'EXCEL SMX'!B:Q,16,0),",","."))/100,"0")*G32 -> 0 | I32: =G32-H32 -> 292.14
A33: 7861033001067 | B33: FT | C33: F DE MESA 350G | D33: =_xlfn.NUMBERVALUE(IFERROR(VLOOKUP(TEXT(A33,"#"),'EXCEL SMX'!B:I,8,0),0)) -> 0 | E33: =_xlfn.NUMBERVALUE(VLOOKUP(A33,'FINAL BODEGA'!A:D,4,0)) -> 0 | F33: =D33*E33 -> 0 | G33: =IFERROR(_xlfn.NUMBERVALUE(SUBSTITUTE(VLOOKUP(TEXT(A33,"#"),'EXCEL SMX'!B:Q,9,0),",",".")),"0")*F33 -> 0 | H33: =IFERROR(_xlfn.NUMBERVALUE(SUBSTITUTE(VLOOKUP(TEXT(A33,"#"),'EXCEL SMX'!B:Q,16,0),",","."))/100,"0")*G33 -> 0 | I33: =G33-H33 -> 0
A34: 7861033001210 | B34: H | C34: DANBO 200G | D34: =_xlfn.NUMBERVALUE(IFERROR(VLOOKUP(TEXT(A34,"#"),'EXCEL SMX'!B:I,8,0),0)) -> 0 | E34: =_xlfn.NUMBERVALUE(VLOOKUP(A34,'FINAL BODEGA'!A:D,4,0)) -> 0 | F34: =D34*E34 -> 0 | G34: =IFERROR(_xlfn.NUMBERVALUE(SUBSTITUTE(VLOOKUP(TEXT(A34,"#"),'EXCEL SMX'!B:Q,9,0),",",".")),"0")*F34 -> 0 | H34: =IFERROR(_xlfn.NUMBERVALUE(SUBSTITUTE(VLOOKUP(TEXT(A34,"#"),'EXCEL SMX'!B:Q,16,0),",","."))/100,"0")*G34 -> 0 | I34: =G34-H34 -> 0
A35: 7861033001616 | B35: H | C35: GOUDA 300G | D35: =_xlfn.NUMBERVALUE(IFERROR(VLOOKUP(TEXT(A35,"#"),'EXCEL SMX'!B:I,8,0),0)) -> 0 | E35: =_xlfn.NUMBERVALUE(VLOOKUP(A35,'FINAL BODEGA'!A:D,4,0)) -> 0 | F35: =D35*E35 -> 0 | G35: =IFERROR(_xlfn.NUMBERVALUE(SUBSTITUTE(VLOOKUP(TEXT(A35,"#"),'EXCEL SMX'!B:Q,9,0),",",".")),"0")*F35 -> 0 | H35: =IFERROR(_xlfn.NUMBERVALUE(SUBSTITUTE(VLOOKUP(TEXT(A35,"#"),'EXCEL SMX'!B:Q,16,0),",","."))/100,"0")*G35 -> 0 | I35: =G35-H35 -> 0
A36: 7861033002163 | B36: H | C36: GOUDA REB 200G | D36: =_xlfn.NUMBERVALUE(IFERROR(VLOOKUP(TEXT(A36,"#"),'EXCEL SMX'!B:I,8,0),0)) -> 0 | E36: =_xlfn.NUMBERVALUE(VLOOKUP(A36,'FINAL BODEGA'!A:D,4,0)) -> 0 | F36: =D36*E36 -> 0 | G36: =IFERROR(_xlfn.NUMBERVALUE(SUBSTITUTE(VLOOKUP(TEXT(A36,"#"),'EXCEL SMX'!B:Q,9,0),",",".")),"0")*F36 -> 0 | H36: =IFERROR(_xlfn.NUMBERVALUE(SUBSTITUTE(VLOOKUP(TEXT(A36,"#"),'EXCEL SMX'!B:Q,16,0),",","."))/100,"0")*G36 -> 0 | I36: =G36-H36 -> 0
A37: 7861033000626 | B37: H | C37: HOL REB 200G | D37: =_xlfn.NUMBERVALUE(IFERROR(VLOOKUP(TEXT(A37,"#"),'EXCEL SMX'!B:I,8,0),0)) -> 24 | E37: =_xlfn.NUMBERVALUE(VLOOKUP(A37,'FINAL BODEGA'!A:D,4,0)) -> 7 | F37: =D37*E37 -> 168 | G37: =IFERROR(_xlfn.NUMBERVALUE(SUBSTITUTE(VLOOKUP(TEXT(A37,"#"),'EXCEL SMX'!B:Q,9,0),",",".")),"0")*F37 -> 470.4 | H37: =IFERROR(_xlfn.NUMBERVALUE(SUBSTITUTE(VLOOKUP(TEXT(A37,"#"),'EXCEL SMX'!B:Q,16,0),",","."))/100,"0")*G37 -> 94.08 | I37: =G37-H37 -> 376.32
A38: 7861033000633 | B38: H | C38: HOL REB 400G | D38: =_xlfn.NUMBERVALUE(IFERROR(VLOOKUP(TEXT(A38,"#"),'EXCEL SMX'!B:I,8,0),0)) -> 12 | E38: =_xlfn.NUMBERVALUE(VLOOKUP(A38,'FINAL BODEGA'!A:D,4,0)) -> 6 | F38: =D38*E38 -> 72 | G38: =IFERROR(_xlfn.NUMBERVALUE(SUBSTITUTE(VLOOKUP(TEXT(A38,"#"),'EXCEL SMX'!B:Q,9,0),",",".")),"0")*F38 -> 388.8 | H38: =IFERROR(_xlfn.NUMBERVALUE(SUBSTITUTE(VLOOKUP(TEXT(A38,"#"),'EXCEL SMX'!B:Q,16,0),",","."))/100,"0")*G38 -> 0 | I38: =G38-H38 -> 388.8
A39: 7861033001432 | B39: H | C39: HOL REB 700G | D39: =_xlfn.NUMBERVALUE(IFERROR(VLOOKUP(TEXT(A39,"#"),'EXCEL SMX'!B:I,8,0),0)) -> 0 | E39: =_xlfn.NUMBERVALUE(VLOOKUP(A39,'FINAL BODEGA'!A:D,4,0)) -> 0 | F39: =D39*E39 -> 0 | G39: =IFERROR(_xlfn.NUMBERVALUE(SUBSTITUTE(VLOOKUP(TEXT(A39,"#"),'EXCEL SMX'!B:Q,9,0),",",".")),"0")*F39 -> 0 | H39: =IFERROR(_xlfn.NUMBERVALUE(SUBSTITUTE(VLOOKUP(TEXT(A39,"#"),'EXCEL SMX'!B:Q,16,0),",","."))/100,"0")*G39 -> 0 | I39: =G39-H39 -> 0
A40: 7861033002071 | B40: H | C40: SE HOL REB 160G | D40: =_xlfn.NUMBERVALUE(IFERROR(VLOOKUP(TEXT(A40,"#"),'EXCEL SMX'!B:I,8,0),0)) -> 0 | E40: =_xlfn.NUMBERVALUE(VLOOKUP(A40,'FINAL BODEGA'!A:D,4,0)) -> 0 | F40: =D40*E40 -> 0 | G40: =IFERROR(_xlfn.NUMBERVALUE(SUBSTITUTE(VLOOKUP(TEXT(A40,"#"),'EXCEL SMX'!B:Q,9,0),",",".")),"0")*F40 -> 0 | H40: =IFERROR(_xlfn.NUMBERVALUE(SUBSTITUTE(VLOOKUP(TEXT(A40,"#"),'EXCEL SMX'!B:Q,16,0),",","."))/100,"0")*G40 -> 0 | I40: =G40-H40 -> 0
...

Sheet PRODS
A1: Q. CRIOLLO 400 GR (UN) | B1: =+VLOOKUP(A1,$D$1:$E$55,2,0) -> 7861033000350 | C1: 7861033000015 | D1: Q. FRESCO 500 GR (UN) | E1: 7861033000015
A2: Q. CRIOLLO 700 GR (UN) | B2: =+VLOOKUP(A2,$D$1:$E$55,2,0) -> 7861033001364 | C2: 7861033000145 | D2: Q. TIERNO 480 GR (UN) | E2: 7861033000145
A3: Q. F DE MESA 350 GR (UN) | B3: =+VLOOKUP(A3,$D$1:$E$55,2,0) -> 7861033001067 | C3: 7861033000312 | D3: Q. FRESCO 700 GR (UN) | E3: 7861033000312
A4: Q. FRESCO 500 GR (UN) | B4: =+VLOOKUP(A4,$D$1:$E$55,2,0) -> 7861033000015 | C4: 7861033000350 | D4: Q. CRIOLLO 400 GR (UN) | E4: 7861033000350
A5: Q. FRESCO 700 GR (UN) | B5: =+VLOOKUP(A5,$D$1:$E$55,2,0) -> 7861033000312 | C5: 7861033000527 | D5: Q. MANABA 400 GR (UN) | E5: 7861033000527
A6: Q. FRESCO BEG 450 GR (UN) | B6: =+VLOOKUP(A6,$D$1:$E$55,2,0) -> 7861033000831 | C6: 7861033000855 | D6: Q. FRESCO DESLACT 450 GR (UN) | E6: 7861033000855
A7: Q. FRESCO BEG 700 GR (UN) | B7: =+VLOOKUP(A7,$D$1:$E$55,2,0) -> 7861033001388 | C7: 7861033000831 | D7: Q. FRESCO BEG 450 GR (UN) | E7: 7861033000831
A8: Q. MANABA 400 GR (UN) | B8: =+VLOOKUP(A8,$D$1:$E$55,2,0) -> 7861033000527 | C8: 7861033001067 | D8: Q. F DE MESA 350 GR (UN) | E8: 7861033001067
A9: Q. TIERNO 480 GR (UN) | B9: =+VLOOKUP(A9,$D$1:$E$55,2,0) -> 7861033000145 | C9: 7861033001364 | D9: Q. CRIOLLO 700 GR (UN) | E9: 7861033001364
A10: Q. FRESCO DESLACT 450 GR (UN) | B10: =+VLOOKUP(A10,$D$1:$E$55,2,0) -> 7861033000855 | C10: 7861033001388 | D10: Q. FRESCO BEG 700 GR (UN) | E10: 7861033001388
A11: Q. MOZZ 200 GR (UN) | B11: =+VLOOKUP(A11,$D$1:$E$55,2,0) -> 7861033001029 | C11: 7861033000022 | D11: Q. MOZZ 500 GR REDONDO (UN) | E11: 7861033000022
A12: Q. MOZZ 700 GR (UN) | B12: =+VLOOKUP(A12,$D$1:$E$55,2,0) -> 7861033000077 | C12: 7861033000091 | D12: Q. MOZZ 500 GR RECT (UN) | E12: 7861033000091
... A56: Q. RICOTA UNTABLE 200 GR (UN) | B56: =+VLOOKUP(A56,$D$1:$E$55,2,0) -> 7861033001500 | C56: 7861033002514 | D56: Q. RICOTA 450 GR (UN) | E56: 7861033002514
A57: Q. RICOTA UNTABLE 400 GR (UN) | B57: =+VLOOKUP(A57,$D$1:$E$55,2,0) -> 7861033001548
A58: Q. MANABA 700G | B58: 7861033001371
A59: Q. MOZZ PIZZA MADURO 700 | B59: 7861033001623
A60: SAN ENRIQUE QUESO CREMOSO 650G | B60: 7861033001982
A61: YOG. FRUTIMORA 180G | B61: 7861033002361
A62: YOG. FRUTIMORA 900G | B62: 7861033002378
A63: YOG. FRUTIMORA 1600G | B63: 7861033002385
A64: YOG. FRUTIMORA LIGHT 180G | B64: 7861033002392
A65: YOG. FRUTIMORA LIGHT 900G | B65: 7861033002408
A66: YOG. FRUTIMORA LIGHT 1600G | B66: 7861033002415
A67: YOG. MARACUMANGO 180G | B67: 7861033002422
A68: YOG. MARACUMANGO 900G | B68: 7861033002439
A69: YOG. MARACUMANGO 1600G | B69: 7861033002446
... A87: Deditos de Queso Mozzarella Bajo en Grasa 80gr | B87: 7861033002231
A88: PARMESANO RALLADO 100 GR | B88: 7861033002521
A89: PARMESANO RALLADO 250 GR | B89: 7861033002538
A90: TACO MIX QUESOS RALLADO 300 GR | B90: 7861033002545
A91: MIX QUESOS EN CUBOS 300 GR | B91: 7861033002552
A92: PIZZA MIX 4 QUESOS 300 GR | B92: 7861033002583
A93: Q. RICOTA 450 GR (UN) | B93: 7861033002514
A94: LA ORIGINAL QUESO CREMOSO 400 GR | B94: 7861042572237
A95: LA ORIGINAL QUESO MOZARELLA 200 GR | B95: 7861042572220
A96: LA ORIGINAL QUESO CHEDDAR REBANADO 150 GR | B96: 7861042572688
A97: LA ORIGINAL QUESO HOLANDES REBANADO 150 GR | B97: 7861042570141
A98: LA ORIGINAL QUESO AMERICANO REBANADO 1 KG | B98: 7861042572244
A99: LA ORIGINAL QUESO RICOTA 250 GR | B99: 7861042571780
A100: QUESO PARMESANO RALLADO 400 GR | B100: 7861033003047
...
